Workbook

Sheet Alert

Sheet SPV_Compensations
C2: SPV Arrangements - Asset Manager Dilution
C3: Compensations
C4: Woodfine Management Corp.
C5: Jennifer M. Woodfine
C6: January 6, 2026
C7: V3
I8: 0.1 | K8: 0.15 | M8: 2/20
C10: Management Fee | I10: ='SPV_Compensations_10 percent'!AL7 -> 800000 | K10: ='SPV_Compensations_15 percent'!AL7 -> 800000 | M10: ='SPV_Compensations_2&20'!Z7 -> 2693097.5 | N10: *
C11: Management Carry | I11: ='SPV_Compensations_10 percent'!AL8 -> 2860705.9 | K11: ='SPV_Compensations_15 percent'!AL8 -> 4291226.2 | M11: ='SPV_Compensations_2&20'!Z8 -> 7454845.4
C12: Distributions | I12: ='SPV_Compensations_10 percent'!AL9 -> 240670.7 | K12: ='SPV_Compensations_15 percent'!AL9 -> 361006.05 | M12: 0
I13: =SUM(I10:I12) -> 3901376.6 | K13: =SUM(K10:K12) -> 5452232.2 | M13: =SUM(M10:M12) -> 10147943 | N13: †
C15: Board of Directors Expense | I15: ='SPV_Compensations_10 percent'!AC8 -> 50000 | K15: ='SPV_Compensations_15 percent'!AC8 -> 50000 | M15: ='SPV_Compensations_2&20'!Q8 -> 30000
C16: Admin Costs | I16: ='SPV_Compensations_10 percent'!AC9 -> 20000 | K16: ='SPV_Compensations_15 percent'!AC9 -> 20000 | M16: ='SPV_Compensations_2&20'!Q9 -> 20000
C17: Working Capital Reserve | I17: ='SPV_Compensations_10 percent'!AC10 -> 0.051 | K17: ='SPV_Compensations_15 percent'!AC10 -> 0.051 | M17: ='SPV_Compensations_2&20'!Q10 -> 0.02
C18: Minimum Cash Position | I18: ='SPV_Compensations_10 percent'!AC11 -> 4463.0538 | K18: ='SPV_Compensations_15 percent'!AC11 -> 4463.0538 | M18: 0
C20: Distribution Yield on Initial Capital | I20: ='SPV_Compensations_10 percent'!AL16 -> 0.19054206 | K20: ='SPV_Compensations_15 percent'!AL16 -> 0.17995621 | M20: ='SPV_Compensations_2&20'!Z16 -> 0.15943835
C21: Market Value | I21: ='SPV_Compensations_10 percent'!AL23 -> 257.48928 | K21: ='SPV_Compensations_15 percent'!AL23 -> 243.18407 | M21: ='SPV_Compensations_2&20'!Z23 -> 229.4077
C23: Discount / Premium vs. Net Asset Value (NAV) | I23: ='SPV_Compensations_10 percent'!AL24 -> -0.20825892 | K23: ='SPV_Compensations_15 percent'!AL24 -> -0.20825892 | M23: ='SPV_Compensations_2&20'!Z24 -> -0.21051812
C25: Compounded Annual Return (Excluding Distributions) | I25: ='SPV_Compensations_10 percent'!AL27 -> 0.12549843 | K25: ='SPV_Compensations_15 percent'!AL27 -> 0.11748549 | M25: ='SPV_Compensations_2&20'!Z27 -> 0.10936893
C26: Distribution Yield to Buyers at Market Value | I26: ='SPV_Compensations_10 percent'!AL28 -> 0.074 | K26: ='SPV_Compensations_15 percent'!AL28 -> 0.074 | M26: ='SPV_Compensations_2&20'!Z28 -> 0.0695
C28: *In the case of the 2/20, the Management Fee calculated on the NAV is accrued rather than distributed due to the size of the Working Capital Reserve that would be required.
C31: † Final Sale must occur
C33: NTD - The pro forma figures above represent preliminary, high-level estimates based on current assumptions and are subject to change

Sheet SPV_Compensations_10 percent
C1: Cash Flow and Valuation
C2: Woodfine Professional Centres Limited Partnership
C3: January 6, 2026
D5: Build Time | E5: Gross Cost per sq. ft. | F5: Portfolio additions in sf. | G5: Capital investment
C6: Phase 1 - initial funding for capital assets | D6: 1 | E6: 310 | F6: =$D$43/$E6 -> 30612.903 | G6: =+F6*E6 -> 9490000 | AA6: SPV Arrangements - Asset Manager Dilution
C7: Phase 2 - first financing | D7: 2 | E7: =+E6 -> 310 | F7: =$D$48/$E7 -> 0 | G7: =+F7*E7 -> 0 | AA7: Unit-based Compensation | AC7: =D21 -> 0.1 | AI7: Management Fee (1% GFV) | AL7: =SUM(E63:L63) -> 800000
C8: Phase 3 - second financing | D8: 2 | E8: =+E7 -> 310 | F8: =$D$49/$E8 -> 0 | G8: =+F8*E8 -> 0 | AA8: =C23 -> Board of Directors Expense | AC8: =D23 -> 50000 | AI8: Unit-based Compenstion (10% Market Value) | AL8: =AL23*(D45-100000) -> 2860705.9
F9: =SUM(F6:F8) -> 30612.903 | G9: =SUM(G6:G8) -> 9490000 | AA9: =C24 -> Admin Costs | AC9: =D24 -> 20000 | AI9: Distributions | AL9: =SUM(E120:L120)*AC7 -> 240670.7
C10: Development Yield | D10: 0.105 | AA10: Working Capital Reserve | AC10: =D34 -> 0.051
AA11: Minimum Cash Position | AC11: =H86 -> 4463.0538
C12: Cap Rate - Public Non Listed | D12: 0.0625 | AE12: Y1 | AF12: Y2 | AG12: Y3 | AH12: Y4 | AI12: Y5 | AJ12: Y6 | AK12: Y7 | AL12: Y8 | AM12: Y9 | AN12: Y10
AA13: Revenue | AE13: - | AF13: - | AG13: - | AH13: =H57/$D45 -> 1.2313356 | AI13: =I57/$D45 -> 1.7164033 | AJ13: =J57/$D45 -> 2.4325658 | AK13: =K57/$D45 -> 3.6293623 | AL13: =L57/$D45 -> 20.577032 | AM13: =M57/$D45 -> 20.679917 | AN13: =N57/$D45 -> 20.783317
AA14: Distributions | AE14: - | AF14: - | AG14: - | AH14: =H122 -> -0.26755361 | AI14: =I122 -> 0.16847218 | AJ14: =J122 -> 0.81335538 | AK14: =K122 -> 1.892099 | AL14: =L122 -> 19.054206 | AM14: =M122 -> 19.157092 | AN14: =N122 -> 19.260491
C15: Total Equity Financing - 1 year | D15: 10000000
C16: Cost per Unit | D16: 100 | AA16: Distribution Yield on Initial Capital | AE16: - | AF16: - | AG16: - | AH16: =AH14/100 -> -0.0026755361 | AI16: =AI14/100 -> 0.0016847218 | AJ16: =AJ14/100 -> 0.0081335538 | AK16: =AK14/100 -> 0.01892099 | AL16: =AL14/100 -> 0.19054206 | AM16: =AM14/100 -> 0.19157092 | AN16: =AN14/100 -> 0.19260491
C17: Issuing Agents Fee | D17: 0
AA18: Asset Value | AE18: =E110 -> 88.470885 | AF18: =F110 -> 87.194839 | AG18: =G110 -> 85.631792 | AH18: =H110 -> 113.86554 | AI18: =I110 -> 114.07497 | AJ18: =J110 -> 185.42026 | AK18: =K110 -> 186.03376 | AL18: =L110 -> 325.21904 | ... AN18: =N110 -> 329.82607
C19: Advisory Fee as percentage of Gross Funded Value | D19: 0.01 | AA19: Total Debt | AE19: =E92/$D45 -> 0 | AF19: =F92/$D45 -> 0 | AG19: =G92/$D45 -> 0 | AH19: =H92/$D45 -> 0 | AI19: =I92/$D45 -> 0 | AJ19: =J92/$D45 -> 0 | AK19: =K92/$D45 -> 0 | AL19: =L92/$D45 -> 0 | ... AN19: =N92/$D45 -> 0
C21: Benetti Holdings Dilution | D21: 0.1 | AA21: Net Asset Value (NAV) | AE21: =E115 -> 88.470885 | AF21: =F115 -> 87.194839 | AG21: =G115 -> 85.631792 | AH21: =H115 -> 113.86554 | AI21: =I115 -> 114.07497 | AJ21: =J115 -> 185.42026 | AK21: =K115 -> 186.03376 | AL21: =L115 -> 325.21904 | ... AN21: =N115 -> 329.82607
C23: Board of Directors Expense | D23: 50000 | AA23: Market Value | AC23: 0.074 | AE23: 100 | AF23: 100 | AG23: 100 | AH23: 125.8 | AI23: 132.1 | AJ23: 171.5 | AK23: 177.3 | AL23: =AL14/AC23 -> 257.48928 | AM23: =AM14/AC23 -> 258.87962 | AN23: =AN14/AC23 -> 260.27691
C24: Admin Costs | D24: 20000 | AH24: =(AH23-AH21)/AH21 -> 0.10481191 | AI24: =(AI23-AI21)/AI21 -> 0.15801043 | AJ24: =(AJ23-AJ21)/AJ21 -> -0.075074119 | AK24: =(AK23-AK21)/AK21 -> -0.04694717 | AL24: =(AL23-AL21)/AL21 -> -0.20825892 | AM24: =(AM23-AM21)/AM21 -> -0.20956846 | AN24: =(AN23-AN21)/AN21 -> -0.21086617
C25: Discount to FMV for buildings under cost | D25: 0 | AA25: Discount / Premium vs. Net Asset Value (NAV)
C27: Issue Costs as a Percentage of Gross Funded Value | D27: 0 | AA27: Compounded Annual Return (Excluding Distributions) | AL27: =((AL23/100)^(1/8))-1 -> 0.12549843
C28: Issuing Agents Fee - First Secured Mortgage Debentures | D28: 0 | AA28: Distribution Yield to Buyers at Market Value | AL28: =AL14/AL23 -> 0.074 | AM28: =AM14/AM23 -> 0.074 | AN28: =AN14/AN23 -> 0.074
C29: Interest Paid to the First Secured Mortgage Debentures | D29: 0
C30: Interest earned on Cash on Hand | D30: 0.02 | AA30: Interest Coverage Ratio | AE30: - | AF30: - | AG30: - | AH30: 0 | AI30: 0 | AJ30: 0 | AK30: 0 | AL30: 0 | AM30: 0 | AN30: 0
C31: Debenture Buy Back (% of EBITDA) | D31: 0 | AA31: Debt vs. Development Cost | AE31: - | AF31: - | AG31: - | AH31: =H106 -> 0 | AI31: =I106 -> 0 | AJ31: =J106 -> 0 | AK31: =K106 -> 0 | AL31: =L106 -> 0 | AM31: =M106 -> 0 | AN31: =N106 -> 0
AA32: Debt to Asset Value | AE32: - | AF32: - | AG32: - | AH32: =AH19/AH18 -> 0 | AI32: =AI19/AI18 -> 0 | AJ32: =AJ19/AJ18 -> 0 | AK32: =AK19/AK18 -> 0 | AL32: =AL19/AL18 -> 0 | AM32: =AM19/AM18 -> 0 | AN32: =AN19/AN18 -> 0
C33: Minimum cash balance | D33: 15000
C34: Working Capital Reserve during development | D34: 0.051 | AA34: Total Expense Ratio (NAV) | AE34: =E117 -> 0.017293998 | AF34: =F117 -> 0.017547086 | AG34: =G117 -> 0.017867375 | AH34: =H117 -> 0.013437036 | AI34: =I117 -> 0.013412367 | AJ34: =J117 -> 0.0082516079 | AK34: =K117 -> 0.008224396 | AL34: =L117 -> 0.0047045686 | ... AN34: =N117 -> 0.004638855
AA35: Total Square Foot - $10 Million Gross Funded Value | AE35: - | AF35: - | AG35: - | AH35: =+F6 -> 30612.903 | AI35: =AH35 -> 30612.903 | AJ35: =+AI35+F7 -> 30612.903 | AK35: =AJ35 -> 30612.903 | AL35: =(D43+D48+D49)/E6 -> 30612.903 | AM35: =AL35 -> 30612.903 | AN35: =AM35 -> 30612.903
C37: Equity Proceeds
C38: Partner Contributions | D38: =D15-D32 -> 10000000 | AA38: Year 8 | AE38: $ | AF38: %
C39: Issuing Agents Fees | D39: =D17*D38 -> 0
C40: Issue Costs | D40: =+D27*D38 -> 0 | AA40: Revenue | AE40: =AL13 -> 20.577032 | AF40: =AE40/AE40 -> 1
C41: Net Proceeds | D41: =D38-D39-D40 -> 10000000
C42: Working Capital | D42: =D34*D38 -> 510000 | AB42: Advisory Fee | AE42: =L63/D45 -> 0.900009 | AF42: =AE42/AE40 -> 0.043738524
C43: Net Equity Funding | D43: =D41-D42 -> 9490000
AB44: Operating and Administrative Expense | AE44: =(L64+L65)/D45 -> 0.6300063 | AF44: =AE44/AE40 -> 0.030616967
C45: Number of Diluted Units | D45: =ROUND(+((D38/D16)/(1-D21)),0)-1 -> 111110 | AB45: Interest Payments | AE45: =(L69/D45)*-1 -> -0.0071898611 | AF45: =AE45/AE40 -> -0.00034941196
...

Sheet SPV_Compensations_15 percent
C1: Cash Flow and Valuation
C2: Woodfine Professional Centres Limited Partnership
C3: January 6, 2026
D5: Build Time | E5: Gross Cost per sq. ft. | F5: Portfolio additions in sf. | G5: Capital investment
C6: Phase 1 - initial funding for capital assets | D6: 1 | E6: 310 | F6: =$D$43/$E6 -> 30612.903 | G6: =+F6*E6 -> 9490000 | AA6: SPV Arrangements - Asset Manager Dilution
C7: Phase 2 - first financing | D7: 2 | E7: =+E6 -> 310 | F7: =$D$48/$E7 -> 0 | G7: =+F7*E7 -> 0 | AA7: Unit-based Compensation | AC7: =D21 -> 0.15 | AI7: Management Fee (1% GFV) | AL7: =SUM(E63:L63) -> 800000
C8: Phase 3 - second financing | D8: 2 | E8: =+E7 -> 310 | F8: =$D$49/$E8 -> 0 | G8: =+F8*E8 -> 0 | AA8: =C23 -> Board of Directors Expense | AC8: =D23 -> 50000 | AI8: Unit-based Compenstion (10% Market Value) | AL8: =AL23*(D45-100000) -> 4291226.2
F9: =SUM(F6:F8) -> 30612.903 | G9: =SUM(G6:G8) -> 9490000 | AA9: =C24 -> Admin Costs | AC9: =D24 -> 20000 | AI9: Distributions | AL9: =SUM(E120:L120)*AC7 -> 361006.05
C10: Development Yield | D10: 0.105 | AA10: Working Capital Reserve | AC10: =D34 -> 0.051
AA11: Minimum Cash Position | AC11: =H86 -> 4463.0538
C12: Cap Rate - Public Non Listed | D12: 0.0625 | AE12: Y1 | AF12: Y2 | AG12: Y3 | AH12: Y4 | AI12: Y5 | AJ12: Y6 | AK12: Y7 | AL12: Y8 | AM12: Y9 | AN12: Y10
AA13: Revenue | AE13: - | AF13: - | AG13: - | AH13: =H57/$D45 -> 1.1629269 | AI13: =I57/$D45 -> 1.6210459 | AJ13: =J57/$D45 -> 2.2974209 | AK13: =K57/$D45 -> 3.4277276 | AL13: =L57/$D45 -> 19.433844 | AM13: =M57/$D45 -> 19.531013 | AN13: =N57/$D45 -> 19.628668
AA14: Distributions | AE14: - | AF14: - | AG14: - | AH14: =H122 -> -0.25268927 | AI14: =I122 -> 0.15911245 | AJ14: =J122 -> 0.7681682 | AK14: =K122 -> 1.7869806 | AL14: =L122 -> 17.995621 | AM14: =M122 -> 18.092791 | AN14: =N122 -> 18.190446
C15: Total Equity Financing - 1 year | D15: 10000000
C16: Cost per Unit | D16: 100 | AA16: Distribution Yield on Initial Capital | AE16: - | AF16: - | AG16: - | AH16: =AH14/100 -> -0.0025268927 | AI16: =AI14/100 -> 0.0015911245 | AJ16: =AJ14/100 -> 0.007681682 | AK16: =AK14/100 -> 0.017869806 | AL16: =AL14/100 -> 0.17995621 | AM16: =AM14/100 -> 0.18092791 | AN16: =AN14/100 -> 0.18190446
C17: Issuing Agents Fee | D17: 0
AA18: Asset Value | AE18: =E110 -> 83.555752 | AF18: =F110 -> 82.350599 | AG18: =G110 -> 80.874389 | AH18: =H110 -> 107.53956 | AI18: =I110 -> 107.73736 | AJ18: =J110 -> 175.11896 | AK18: =K110 -> 175.69837 | AL18: =L110 -> 307.15101 | ... AN18: =N110 -> 311.50209
C19: Advisory Fee as percentage of Gross Funded Value | D19: 0.01 | AA19: Total Debt | AE19: =E92/$D45 -> 0 | AF19: =F92/$D45 -> 0 | AG19: =G92/$D45 -> 0 | AH19: =H92/$D45 -> 0 | AI19: =I92/$D45 -> 0 | AJ19: =J92/$D45 -> 0 | AK19: =K92/$D45 -> 0 | AL19: =L92/$D45 -> 0 | ... AN19: =N92/$D45 -> 0
C21: Benetti Holdings Dilution | D21: 0.15 | AA21: Net Asset Value (NAV) | AE21: =E115 -> 83.555752 | AF21: =F115 -> 82.350599 | AG21: =G115 -> 80.874389 | AH21: =H115 -> 107.53956 | AI21: =I115 -> 107.73736 | AJ21: =J115 -> 175.11896 | AK21: =K115 -> 175.69837 | AL21: =L115 -> 307.15101 | ... AN21: =N115 -> 311.50209
C23: Board of Directors Expense | D23: 50000 | AA23: Market Value | AC23: 0.074 | AE23: 100 | AF23: 100 | AG23: 100 | AH23: 125.8 | AI23: 132.1 | AJ23: 171.5 | AK23: 177.3 | AL23: =AL14/AC23 -> 243.18407 | AM23: =AM14/AC23 -> 244.49717 | AN23: =AN14/AC23 -> 245.81683
C24: Admin Costs | D24: 20000 | AH24: =(AH23-AH21)/AH21 -> 0.16980202 | AI24: =(AI23-AI21)/AI21 -> 0.22612991 | AJ24: =(AJ23-AJ21)/AJ21 -> -0.020665735 | AK24: =(AK23-AK21)/AK21 -> 0.0091157699 | AL24: =(AL23-AL21)/AL21 -> -0.20825892 | AM24: =(AM23-AM21)/AM21 -> -0.20956846 | AN24: =(AN23-AN21)/AN21 -> -0.21086617
C25: Discount to FMV for buildings under cost | D25: 0 | AA25: Discount / Premium vs. Net Asset Value (NAV)
C27: Issue Costs as a Percentage of Gross Funded Value | D27: 0 | AA27: Compounded Annual Return (Excluding Distributions) | AL27: =((AL23/100)^(1/8))-1 -> 0.11748549
C28: Issuing Agents Fee - First Secured Mortgage Debentures | D28: 0 | AA28: Distribution Yield to Buyers at Market Value | AL28: =AL14/AL23 -> 0.074 | AM28: =AM14/AM23 -> 0.074 | AN28: =AN14/AN23 -> 0.074
C29: Interest Paid to the First Secured Mortgage Debentures | D29: 0
C30: Interest earned on Cash on Hand | D30: 0.02 | AA30: Interest Coverage Ratio | AE30: - | AF30: - | AG30: - | AH30: 0 | AI30: 0 | AJ30: 0 | AK30: 0 | AL30: 0 | AM30: 0 | AN30: 0
C31: Debenture Buy Back (% of EBITDA) | D31: 0 | AA31: Debt vs. Development Cost | AE31: - | AF31: - | AG31: - | AH31: =H106 -> 0 | AI31: =I106 -> 0 | AJ31: =J106 -> 0 | AK31: =K106 -> 0 | AL31: =L106 -> 0 | AM31: =M106 -> 0 | AN31: =N106 -> 0
AA32: Debt to Asset Value | AE32: - | AF32: - | AG32: - | AH32: =AH19/AH18 -> 0 | AI32: =AI19/AI18 -> 0 | AJ32: =AJ19/AJ18 -> 0 | AK32: =AK19/AK18 -> 0 | AL32: =AL19/AL18 -> 0 | AM32: =AM19/AM18 -> 0 | AN32: =AN19/AN18 -> 0
C33: Minimum cash balance | D33: 15000
C34: Working Capital Reserve during development | D34: 0.051 | AA34: Total Expense Ratio (NAV) | AE34: =E117 -> 0.017293998 | AF34: =F117 -> 0.017547086 | AG34: =G117 -> 0.017867375 | AH34: =H117 -> 0.013437036 | AI34: =I117 -> 0.013412367 | AJ34: =J117 -> 0.0082516079 | AK34: =K117 -> 0.008224396 | AL34: =L117 -> 0.0047045686 | ... AN34: =N117 -> 0.004638855
AA35: Total Square Foot - $10 Million Gross Funded Value | AE35: - | AF35: - | AG35: - | AH35: =+F6 -> 30612.903 | AI35: =AH35 -> 30612.903 | AJ35: =+AI35+F7 -> 30612.903 | AK35: =AJ35 -> 30612.903 | AL35: =(D43+D48+D49)/E6 -> 30612.903 | AM35: =AL35 -> 30612.903 | AN35: =AM35 -> 30612.903
C37: Equity Proceeds
C38: Partner Contributions | D38: =D15-D32 -> 10000000 | AA38: Year 8 | AE38: $ | AF38: %
C39: Issuing Agents Fees | D39: =D17*D38 -> 0
C40: Issue Costs | D40: =+D27*D38 -> 0 | AA40: Revenue | AE40: =AL13 -> 19.433844 | AF40: =AE40/AE40 -> 1
C41: Net Proceeds | D41: =D38-D39-D40 -> 10000000
C42: Working Capital | D42: =D34*D38 -> 510000 | AB42: Advisory Fee | AE42: =L63/D45 -> 0.85000765 | AF42: =AE42/AE40 -> 0.043738524
C43: Net Equity Funding | D43: =D41-D42 -> 9490000
AB44: Operating and Administrative Expense | AE44: =(L64+L65)/D45 -> 0.59500536 | AF44: =AE44/AE40 -> 0.030616967
C45: Number of Diluted Units | D45: =ROUND(+((D38/D16)/(1-D21)),0)-1 -> 117646 | AB45: Interest Payments | AE45: =(L69/D45)*-1 -> -0.0067904176 | AF45: =AE45/AE40 -> -0.00034941196
...

Sheet SPV_Compensations_2&20
C1: Cash Flow and Valuation
C2: Woodfine Professional Centres Limited Partnership
C3: January 6, 2026
D5: Build Time | E5: Gross Cost per sq. ft. | F5: Portfolio additions in sf. | G5: Capital investment
C6: Phase 1 - initial funding for capital assets | D6: 1 | E6: 310 | F6: =$D$43/$E6 -> 31612.903 | G6: =+F6*E6 -> 9800000 | O6: SPV Arrangements - Asset Manager Dilution
C7: Phase 2 - first financing | D7: 2 | E7: =+E6 -> 310 | F7: =$D$48/$E7 -> 0 | G7: =+F7*E7 -> 0 | O7: Unit-based Compensation | Q7: =D21 -> 0 | X7: Management Fee (2% NAV) | Z7: =M63 -> 2693097.5
C8: Phase 3 - second financing | D8: 2 | E8: =+E7 -> 310 | F8: =$D$49/$E8 -> 0 | G8: =+F8*E8 -> 0 | O8: =C23 -> Board of Directors Expense | Q8: =D23 -> 30000 | X8: Management Carry (20%) | Z8: =N100 -> 7454845.4
F9: =SUM(F6:F8) -> 31612.903 | G9: =SUM(G6:G8) -> 9800000 | O9: =C24 -> Admin Costs | Q9: =D24 -> 20000
C10: Development Yield | D10: 0.105 | O10: Working Capital Reserve | Q10: =D34 -> 0.02
C12: Cap Rate - Public Non Listed | D12: 0.0625 | S12: Y1 | T12: Y2 | U12: Y3 | V12: Y4 | W12: Y5 | X12: Y6 | Y12: Y7 | Z12: Y8 | AA12: Y9 | AB12: Y10
O13: Revenue | S13: - | T13: - | U13: - | V13: =H57/$D45 -> 1.4128426 | W13: =I57/$D45 -> 1.9694125 | X13: =J57/$D45 -> 2.7911421 | Y13: =K57/$D45 -> 4.1643543 | Z13: =L57/$D45 -> 23.610223 | AA13: 0 | AB13: 0
O14: Distributions | S14: - | T14: - | U14: - | V14: =H122 -> -1.540413 | W14: =I122 -> -1.046106 | X14: =J122 -> -1.7823518 | Y14: =K122 -> -0.56141923 | Z14: =L122 -> 15.943835 | AA14: 0 | AB14: 0
C15: Total Equity Financing - 1 year | D15: 10000000
C16: Cost per Unit | D16: 100 | O16: Distribution Yield on Initial Capital | S16: - | T16: - | U16: - | V16: =V14/100 -> -0.01540413 | W16: =W14/100 -> -0.01046106 | X16: =X14/100 -> -0.017823518 | Y16: =Y14/100 -> -0.0056141923 | Z16: =Z14/100 -> 0.15943835 | AA16: =AA14/100 -> 0 | AB16: =AB14/100 -> 0
C17: Issuing Agents Fee | D17: 0
O18: Asset Value | S18: =E110 -> 98.026488 | T18: =F110 -> 98.248182 | U18: =G110 -> 98.174287 | V18: =H110 -> 130.60398 | W18: =I110 -> 130.8228 | X18: =J110 -> 212.58118 | Y18: =K110 -> 213.04388 | Z18: =L110 -> 290.58007 | AA18: 0 | AB18: 0
C19: Advisory Fee as percentage of Gross Funded Value | D19: 0.02 | O19: Total Debt | S19: =E92/$D45 -> 0 | T19: =F92/$D45 -> 0 | U19: =G92/$D45 -> 0 | V19: =H92/$D45 -> 0 | W19: =I92/$D45 -> 0 | X19: =J92/$D45 -> 0 | Y19: =K92/$D45 -> 0 | Z19: =L92/$D45 -> 0 | AA19: 0 | AB19: 0
C21: Benetti Holdings Dilution | D21: 0 | O21: Net Asset Value (NAV) | S21: =E115 -> 98.026488 | T21: =F115 -> 98.248182 | U21: =G115 -> 98.174287 | V21: =H115 -> 130.60398 | W21: =I115 -> 130.8228 | X21: =J115 -> 212.58118 | Y21: =K115 -> 213.04388 | Z21: =L115 -> 290.58007 | AA21: 0 | AB21: 0
C23: Board of Directors Expense | D23: 30000 | O23: Market Value | Q23: 0.0695 | S23: 100 | T23: 100 | U23: 100 | V23: 125.8 | W23: 132.1 | X23: 171.5 | Y23: 177.3 | Z23: =Z14/Q23 -> 229.4077 | AA23: =AA14/Q23 -> 0 | AB23: =AB14/Q23 -> 0
C24: Admin Costs | D24: 20000 | V24: =(V23-V21)/V21 -> -0.036782806 | W24: =(W23-W21)/W21 -> 0.0097627899 | X24: =(X23-X21)/X21 -> -0.19324936 | Y24: =(Y23-Y21)/Y21 -> -0.16777709 | Z24: =(Z23-Z21)/Z21 -> -0.21051812 | AA24: 0 | AB24: 0
C25: Discount to FMV for buildings under cost | D25: 0 | O25: Discount / Premium vs. Net Asset Value (NAV)
C27: Issue Costs as a Percentage of Gross Funded Value | D27: 0 | O27: Compounded Annual Return (Excluding Distributions) | Z27: =((Z23/100)^(1/8))-1 -> 0.10936893
C28: Issuing Agents Fee - First Secured Mortgage Debentures | D28: 0 | O28: Distribution Yield to Buyers at Market Value | Z28: =Z14/Z23 -> 0.0695 | AA28: 0 | AB28: 0
C29: Interest Paid to the First Secured Mortgage Debentures | D29: 0
C30: Interest earned on Cash on Hand | D30: 0 | O30: Interest Coverage Ratio | S30: - | T30: - | U30: - | V30: 0 | W30: 0 | X30: 0 | Y30: 0 | Z30: 0 | AA30: 0 | AB30: 0
C31: Debenture Buy Back (% of EBITDA) | D31: 0 | O31: Debt vs. Development Cost | S31: - | T31: - | U31: - | V31: =H106 -> 0 | W31: =I106 -> 0 | X31: =J106 -> 0 | Y31: =K106 -> 0 | Z31: =L106 -> 0 | AA31: 0 | AB31: 0
O32: Debt to Asset Value | S32: - | T32: - | U32: - | V32: =V19/V18 -> 0 | W32: =W19/W18 -> 0 | X32: =X19/X18 -> 0 | Y32: =Y19/Y18 -> 0 | Z32: =Z19/Z18 -> 0 | AA32: 0 | AB32: 0
C33: Minimum cash balance | D33: 15000
C34: Working Capital Reserve during development | D34: 0.02 | O34: Total Expense Ratio (NAV) | S34: =E117 -> 0.025401552 | T34: =F117 -> 0.025293582 | U34: =G117 -> 0.025199797 | V34: =H117 -> 0.023922798 | W34: =I117 -> 0.023938888 | X34: =J117 -> 0.022445698 | Y34: =K117 -> 0.022474963 | Z34: =L117 -> 0.026383045 | AA34: 0 | AB34: 0
O35: Total Square Foot - $10 Million Gross Funded Value | S35: - | T35: - | U35: - | V35: =+F6 -> 31612.903 | W35: =V35 -> 31612.903 | X35: =+W35+F7 -> 31612.903 | Y35: =X35 -> 31612.903 | Z35: =(D43+D48+D49)/E6 -> 31612.903 | AA35: =Z35 -> 31612.903 | AB35: =AA35 -> 31612.903
C37: Equity Proceeds
C38: Partner Contributions | D38: =D15-D32 -> 10000000 | O38: Year 8 | S38: $ | T38: %
C39: Issuing Agents Fees | D39: =D17*D38 -> 0
C40: Issue Costs | D40: =+D27*D38 -> 0 | O40: Revenue | S40: =Z13 -> 23.610223 | T40: =S40/S40 -> 1
C41: Net Proceeds | D41: =D38-D39-D40 -> 10000000
C42: Working Capital | D42: =D34*D38 -> 200000 | P42: Advisory Fee | S42: =L63/D45 -> 7.1663823 | T42: =S42/S40 -> 0.30352879
C43: Net Equity Funding | D43: =D41-D42 -> 9800000
P44: Operating and Administrative Expense | S44: =(L64+L65)/D45 -> 0.500005 | T44: =S44/S40 -> 0.021177479
C45: Number of Diluted Units | D45: =ROUND(+((D38/D16)/(1-D21)),0)-1 -> 99999 | P45: Interest Payments | S45: =(L69/D45)*-1 -> 0 | T45: =S45/S40 -> 0
C47: Debt Proceeds | E47: Gross borrowing | O47: Distributable Income
...
