Workbook

Sheet Alert

Sheet WCP_42M
C2: Cash Flow and Valuation
C3: Woodfine Capital Projects Inc.
C4: Mathew Woodfine
C5: January 6, 2026
C6: V3
B9: 1 | C9: Number of Common Shares | F9: 10000000
B10: 2 | C10: Price per Share — CAD | F10: 20
B11: 3 | C11: CAD-USD | F11: 1.3372
B12: 4 | C12: CAD-EUR | F12: 1.4657
B13: 5 | C13: Financing Activity — WCP Common Shares | F13: 42000000
B14: 6
B15: 7 | C15: WCP Pro Forma Income Statement
B16: 8 | C16: ** In Canadian Dollars
B17: 9 | C17: Revenue and Assets from the Woodfine LPs
B18: 10
B19: 11 | G19: Y0 | H19: Y0 | I19: Y1 | J19: Y2 | K19: Y3 | L19: Y4 | M19: Y5 | N19: Y6 | O19: Y7 | P19: Y8 | Q19: Y9 | R19: Y10
B20: 12 | C20: Woodfine Professional Centres Limited Partnership (Canada) — C$250 million GFV
B21: 13 | D21: Advisory Fee | G21: =('INPUT_PCLP 1_250M'!E63)*(1/3) -> 833333.33 | H21: =('INPUT_PCLP 1_250M'!F63)*(2/3) -> 1666666.7 | I21: =('INPUT_PCLP 1_250M'!G63)*(3/3) -> 2500000 | J21: =('INPUT_PCLP 1_250M'!H63)*(3/3) -> 2500000 | K21: =('INPUT_PCLP 1_250M'!I63)*(3/3) -> 2500000 | L21: =('INPUT_PCLP 1_250M'!J63)*(3/3) -> 2500000 | M21: =('INPUT_PCLP 1_250M'!K63)*(3/3) -> 2500000 | N21: =('INPUT_PCLP 1_250M'!L63)*(3/3) -> 2500000 | O21: =('INPUT_PCLP 1_250M'!M63)*(3/3) -> 2500000 | P21: =('INPUT_PCLP 1_250M'!N63)*(3/3) -> 2500000 | ... R21: =('INPUT_PCLP 1_250M'!P63)*(3/3) -> 2500000
B22: 14 | D22: Distributions | G22: =('INPUT_PCLP 1_250M'!E120)*(1/10) -> 0 | H22: =('INPUT_PCLP 1_250M'!F120)*(1/10) -> 0 | I22: =('INPUT_PCLP 1_250M'!G120)*(1/10) -> 0 | J22: =('INPUT_PCLP 1_250M'!H120)*(1/10) -> 400461.48 | K22: =('INPUT_PCLP 1_250M'!I120)*(1/10) -> 558217.75 | L22: =('INPUT_PCLP 1_250M'!J120)*(1/10) -> 791131.91 | M22: =('INPUT_PCLP 1_250M'!K120)*(1/10) -> 1180360.4 | N22: =('INPUT_PCLP 1_250M'!L120)*(1/10) -> 6692171.2 | ... R22: =('INPUT_PCLP 1_250M'!P120)*(1/10) -> 6827021.8
B23: 15 | D23: Net Asset Value — Public Non-Listed | G23: =('INPUT_PCLP 1_250M'!E114)*(1/10) -> 27785000 | H23: =('INPUT_PCLP 1_250M'!F114)*(1/10) -> 27847838 | I23: =('INPUT_PCLP 1_250M'!G114)*(1/10) -> 27826893 | J23: =('INPUT_PCLP 1_250M'!H114)*(1/10) -> 37018888 | K23: =('INPUT_PCLP 1_250M'!I114)*(1/10) -> 37080913 | L23: =('INPUT_PCLP 1_250M'!J114)*(1/10) -> 60254816 | M23: =('INPUT_PCLP 1_250M'!K114)*(1/10) -> 60385967 | N23: =('INPUT_PCLP 1_250M'!L114)*(1/10) -> 1.0565254e+08 | ... R23: =('INPUT_PCLP 1_250M'!P114)*(1/10) -> 1.2658516e+08
B24: 16
B25: 17 | C25: Woodfine Professional Centres 2 Limited Partnership (US) — US$500 million GFV
B26: 18 | D26: Advisory Fee | H26: =(G21*2)*$F11 -> 2228666.7 | I26: =(H21*2)*$F11 -> 4457333.3 | J26: =(I21*2)*$F11 -> 6686000 | K26: =(J21*2)*$F11 -> 6686000 | L26: =(K21*2)*$F11 -> 6686000 | M26: =(L21*2)*$F11 -> 6686000 | N26: =(M21*2)*$F11 -> 6686000 | O26: =(N21*2)*$F11 -> 6686000 | ... R26: =(Q21*2)*$F11 -> 6686000
B27: 19 | D27: Distributions | H27: =(G22*2)*$F11 -> 0 | I27: =(H22*2)*$F11 -> 0 | J27: =(I22*2)*$F11 -> 0 | K27: =(J22*2)*$F11 -> 1070994.2 | L27: =(K22*2)*$F11 -> 1492897.5 | M27: =(L22*2)*$F11 -> 2115803.2 | N27: =(M22*2)*$F11 -> 3156755.9 | O27: =(N22*2)*$F11 -> 17897543 | ... R27: =(Q22*2)*$F11 -> 18167350
B28: 20 | D28: Net Asset Value — Public Non-Listed | H28: =(G23*2)*$F11 -> 74308204 | I28: =(H23*2)*$F11 -> 74476258 | J28: =(I23*2)*$F11 -> 74420242 | K28: =(J23*2)*$F11 -> 99003315 | L28: =(K23*2)*$F11 -> 99169193 | M28: =(L23*2)*$F11 -> 1.6114548e+08 | N28: =(M23*2)*$F11 -> 1.6149623e+08 | O28: =(N23*2)*$F11 -> 2.8255716e+08 | ... R28: =(Q23*2)*$F11 -> 3.3651067e+08
B29: 21
B30: 22 | C30: Woodfine Professional Centres 3 Limited Partnership (Spain) — EUR$250 million GFV
B31: 23 | D31: Advisory Fee | H31: =(G21)*$F12 -> 1221416.7 | I31: =(H21)*$F12 -> 2442833.3 | J31: =(I21)*$F12 -> 3664250 | K31: =(J21)*$F12 -> 3664250 | L31: =(K21)*$F12 -> 3664250 | M31: =(L21)*$F12 -> 3664250 | N31: =(M21)*$F12 -> 3664250 | O31: =(N21)*$F12 -> 3664250 | ... R31: =(Q21)*$F12 -> 3664250
B32: 24 | D32: Distributions | H32: =(G22)*$F12 -> 0 | I32: =(H22)*$F12 -> 0 | J32: =(I22)*$F12 -> 0 | K32: =(J22)*$F12 -> 586956.39 | L32: =(K22)*$F12 -> 818179.76 | M32: =(L22)*$F12 -> 1159562 | N32: =(M22)*$F12 -> 1730054.3 | O32: =(N22)*$F12 -> 9808715.3 | ... R32: =(Q22)*$F12 -> 9956582.9
B33: 25 | D33: Net Asset Value — Public Non-Listed | H33: =(G23)*$F12 -> 40724474 | I33: =(H23)*$F12 -> 40816576 | J33: =(I23)*$F12 -> 40785877 | K33: =(J23)*$F12 -> 54258585 | L33: =(K23)*$F12 -> 54349494 | M33: =(L23)*$F12 -> 88315484 | N33: =(M23)*$F12 -> 88507712 | O33: =(N23)*$F12 -> 1.5485493e+08 | ... R33: =(Q23)*$F12 -> 1.8442405e+08
B34: 26
B35: 27 | C35: Woodfine Professional Centres 4 Limited Partnership (Mexico) — US$250 million GFV
B36: 28 | D36: Advisory Fee | I36: =(G21)*$F11 -> 1114333.3 | J36: =(H21)*$F11 -> 2228666.7 | K36: =(I21)*$F11 -> 3343000 | L36: =(J21)*$F11 -> 3343000 | M36: =(K21)*$F11 -> 3343000 | N36: =(L21)*$F11 -> 3343000 | O36: =(M21)*$F11 -> 3343000 | P36: =(N21)*$F11 -> 3343000 | ... R36: =(P21)*$F11 -> 3343000
B37: 29 | D37: Distributions | I37: =(G22)*$F11 -> 0 | J37: =(H22)*$F11 -> 0 | K37: =(I22)*$F11 -> 0 | L37: =(J22)*$F11 -> 535497.09 | M37: =(K22)*$F11 -> 746448.77 | N37: =(L22)*$F11 -> 1057901.6 | O37: =(M22)*$F11 -> 1578377.9 | P37: =(N22)*$F11 -> 8948771.3 | ... R37: =(P22)*$F11 -> 9038482.8
B38: 30 | D38: Net Asset Value — Public Non-Listed | I38: =(G23)*$F11 -> 37154102 | J38: =(H23)*$F11 -> 37238129 | K38: =(I23)*$F11 -> 37210121 | L38: =(J23)*$F11 -> 49501658 | M38: =(K23)*$F11 -> 49584596 | N38: =(L23)*$F11 -> 80572740 | O38: =(M23)*$F11 -> 80748115 | P38: =(N23)*$F11 -> 1.4127858e+08 | ... R38: =(P23)*$F11 -> 1.4328213e+08
B39: 31
B40: 32 | C40: Woodfine Vertical Warehouse Limited Partnership (US) — US$250 million GFV
B41: 33 | D41: Advisory Fee | J41: =(G21)*$F11 -> 1114333.3 | K41: =(H21)*$F11 -> 2228666.7 | L41: =(I21)*$F11 -> 3343000 | M41: =(J21)*$F11 -> 3343000 | N41: =(K21)*$F11 -> 3343000 | O41: =(L21)*$F11 -> 3343000 | P41: =(M21)*$F11 -> 3343000 | Q41: =(N21)*$F11 -> 3343000 | R41: =(O21)*$F11 -> 3343000
B42: 34 | D42: Distributions | J42: =(G22)*$F12 -> 0 | K42: =(H22)*$F12 -> 0 | L42: =(I22)*$F12 -> 0 | M42: =(J22)*$F12 -> 586956.39 | N42: =(K22)*$F12 -> 818179.76 | O42: =(L22)*$F12 -> 1159562 | P42: =(M22)*$F12 -> 1730054.3 | Q42: =(N22)*$F12 -> 9808715.3 | R42: =(O22)*$F12 -> 9857758.9
B43: 35 | D43: Net Asset Value — Public Non-Listed | J43: =(G23)*$F11 -> 37154102 | K43: =(H23)*$F11 -> 37238129 | L43: =(I23)*$F11 -> 37210121 | M43: =(J23)*$F11 -> 49501658 | N43: =(K23)*$F11 -> 49584596 | O43: =(L23)*$F11 -> 80572740 | P43: =(M23)*$F11 -> 80748115 | Q43: =(N23)*$F11 -> 1.4127858e+08 | R43: =(O23)*$F11 -> 1.4227786e+08
...

Sheet INPUT_PCLP 1_250M
C1: Cash Flow and Valuation
C2: Woodfine Professional Centres Limited Partnership
C3: January 6, 2026
D5: Build Time | E5: Gross Cost per sq. ft. | F5: Portfolio additions in sf. | G5: Capital investment
C6: Phase 1 - initial funding for capital assets | D6: 3 | E6: 310 | F6: =$D$43/$E6 -> 699596.77 | G6: =+F6*E6 -> 216875000
C7: Phase 2 - first financing | D7: 2 | E7: =+E6 -> 310 | F7: =$D$48/$E7 -> 1095161.3 | G7: =+F7*E7 -> 339500000
C8: Phase 3 - second financing | D8: 2 | E8: =+E7 -> 310 | F8: =$D$49/$E8 -> 2112096.8 | G8: =+F8*E8 -> 6.5475e+08
F9: =SUM(F6:F8) -> 3906854.8 | G9: =SUM(G6:G8) -> 1211125000
C10: Development Yield | D10: 0.105
C12: Cap Rate - Public Non Listed | D12: 0.0625 | AE12: Y1 | AF12: Y2 | AG12: Y3 | AH12: Y4 | AI12: Y5 | AJ12: Y6 | AK12: Y7 | AL12: Y8 | AM12: Y9 | AN12: Y10
AA13: Revenue | AE13: - | AF13: - | AG13: - | AH13: =H57/$D45 -> 8.1978773 | AI13: =I57/$D45 -> 8.1978773 | AJ13: =J57/$D45 -> 21.030981 | AK13: =K57/$D45 -> 21.030981 | AL13: =L57/$D45 -> 45.780538 | AM13: =M57/$D45 -> 45.780538 | AN13: =N57/$D45 -> 45.780538
AA14: Distributions | AE14: - | AF14: - | AG14: - | AH14: =H122 -> 1.4416617 | AI14: =I122 -> 2.0095845 | AJ14: =J122 -> 2.8480757 | AK14: =K122 -> 4.2492987 | AL14: =L122 -> 24.091823 | AM14: =M122 -> 24.212282 | AN14: =N122 -> 24.333344
C15: Total Equity Financing - 1 year | D15: 250000000
C16: Cost per Unit | D16: 100 | AA16: Distribution Yield on Initial Capital | AE16: - | AF16: - | AG16: - | AH16: =AH14/100 -> 0.014416617 | AI16: =AI14/100 -> 0.020095845 | AJ16: =AJ14/100 -> 0.028480757 | AK16: =AK14/100 -> 0.042492987 | AL16: =AL14/100 -> 0.24091823 | AM16: =AM14/100 -> 0.24212282 | AN16: =AN14/100 -> 0.24333344
C17: Issuing Agents Fee | D17: 0.06
AA18: Asset Value | AE18: =E110 -> 100.02603 | AF18: =F110 -> 100.25224 | AG18: =G110 -> 100.17684 | AH18: =H110 -> 196.26805 | AI18: =I110 -> 259.49136 | AJ18: =J110 -> 464.41747 | AK18: =K110 -> 572.79231 | AL18: =L110 -> 733.07516 | ... AN18: =N110 -> 733.07516
C19: Advisory Fee as percentage of Gross Funded Value | D19: 0.01 | AA19: Total Debt | AE19: =E92/$D45 -> 0 | AF19: =F92/$D45 -> 0 | AG19: =G92/$D45 -> 0 | AH19: =H92/$D45 -> 63.000018 | AI19: =I92/$D45 -> 126.00004 | AJ19: =J92/$D45 -> 247.50007 | AK19: =K92/$D45 -> 355.40277 | AL19: =L92/$D45 -> 352.7259 | ... AN19: =N92/$D45 -> 347.33194
C21: Benetti Holdings Dilution | D21: 0.1 | AA21: Net Asset Value (NAV) | AE21: =E115 -> 100.02603 | AF21: =F115 -> 100.25224 | AG21: =G115 -> 100.17684 | AH21: =H115 -> 133.26804 | AI21: =I115 -> 133.49132 | AJ21: =J115 -> 216.9174 | AK21: =K115 -> 217.38954 | AL21: =L115 -> 380.34926 | ... AN21: =N115 -> 385.74322
C23: Board of Directors Expense | D23: 450000 | AA23: Market Value | AC23: 0.08 | AE23: 100 | AF23: 100 | AG23: 100 | AH23: 125.8 | AI23: 132.1 | AJ23: 171.5 | AK23: 177.3 | AL23: =AL14/AC23 -> 301.14779 | AM23: =AM14/AC23 -> 302.65353 | AN23: =AN14/AC23 -> 304.1668
C24: Admin Costs | D24: 500000 | AH24: =(AH23-AH21)/AH21 -> -0.05603771 | AI24: =(AI23-AI21)/AI21 -> -0.01042257 | AJ24: =(AJ23-AJ21)/AJ21 -> -0.20937647 | AK24: =(AK23-AK21)/AK21 -> -0.18441339 | AL24: =(AL23-AL21)/AL21 -> -0.20823353 | AM24: =(AM23-AM21)/AM21 -> -0.20986342 | AN24: =(AN23-AN21)/AN21 -> -0.21147856
C25: Discount to FMV for buildings under cost | D25: 0 | AA25: Discount / Premium vs. Net Asset Value (NAV)
C27: Issue Costs as a Percentage of Gross Funded Value | D27: 0.01 | AA27: Compounded Annual Return (Excluding Distributions) | AL27: =((AL23/100)^(1/8))-1 -> 0.14775042
C28: Issuing Agents Fee - First Secured Mortgage Debentures | D28: 0.03 | AA28: Distribution Yield to Buyers at Market Value | AL28: =AL14/AL23 -> 0.08 | AM28: =AM14/AM23 -> 0.08 | AN28: =AN14/AN23 -> 0.08
C29: Interest Paid to the First Secured Mortgage Debentures | D29: 0.05
C30: Interest earned on Cash on Hand | D30: 0.0005 | AA30: Interest Coverage Ratio | AE30: - | AF30: - | AG30: - | AH30: =H74 -> 2.0176724 | AI30: =I74 -> 1.472765 | AJ30: =J74 -> 1.3390161 | AK30: =K74 -> 1.313352 | AL30: =L74 -> 2.5064111 | AM30: =M74 -> 2.5254328 | AN30: =N74 -> 2.5448428
C31: Debenture Buy Back (% of EBITDA) | D31: 0.1 | AA31: Debt vs. Development Cost | AE31: - | AF31: - | AG31: - | AH31: =H106 -> 0.45263498 | AI31: =I106 -> 0.62907212 | AJ31: =J106 -> 0.77793494 | AK31: =K106 -> 0.81513439 | AL31: =L106 -> 0.80899485 | AM31: =M106 -> 0.80282462 | AN31: =N106 -> 0.79662353
AA32: Debt to Asset Value | AE32: - | AF32: - | AG32: - | AH32: =AH19/AH18 -> 0.32098967 | AI32: =AI19/AI18 -> 0.48556544 | AJ32: =AJ19/AJ18 -> 0.53292584 | AK32: =AK19/AK18 -> 0.62047406 | AL32: =AL19/AL18 -> 0.48115926 | AM32: =AM19/AM18 -> 0.47748944 | AN32: =AN19/AN18 -> 0.47380127
C33: Minimum cash balance | D33: 250000
C34: Working Capital Reserve during development | D34: 0.0625 | AA34: Total Expense Ratio (NAV) | AE34: =E117 -> 0.012416772 | AF34: =F117 -> 0.012388754 | AG34: =G117 -> 0.012398079 | AH34: =H117 -> 0.0093195667 | AI34: =I117 -> 0.0093039781 | AJ34: =J117 -> 0.0057256834 | AK34: =K117 -> 0.0057132479 | AL34: =L117 -> 0.0032654207 | ... AN34: =N117 -> 0.0032197594
AA35: Total Square Foot - $250 Million Gross Funded Value | AE35: - | AF35: - | AG35: - | AH35: =+F6 -> 699596.77 | AI35: =AH35 -> 699596.77 | AJ35: =+AI35+F7 -> 1794758.1 | AK35: =AJ35 -> 1794758.1 | AL35: =(D43+D48+D49)/E6 -> 3906854.8 | AM35: =AL35 -> 3906854.8 | AN35: =AM35 -> 3906854.8
C37: Equity Proceeds
C38: Partner Contributions | D38: =D15-D32 -> 250000000 | AA38: Year 8 | AE38: $ | AF38: %
C39: Issuing Agents Fees | D39: =D17*D38 -> 15000000
C40: Issue Costs | D40: =+D27*D38 -> 2500000 | AA40: Revenue | AE40: =AL13 -> 45.780538 | AF40: =AE40/AE40 -> 1
C41: Net Proceeds | D41: =D38-D39-D40 -> 232500000
C42: Working Capital | D42: =D34*D38 -> 15625000 | AB42: Advisory Fee | AE42: =L63/D45 -> 0.90000025 | AF42: =AE42/AE40 -> 0.019659014
C43: Net Equity Funding | D43: =D41-D42 -> 216875000
AB44: Operating and Administrative Expense | AE44: =(L64+L65)/D45 -> 0.3420001 | AF44: =AE44/AE40 -> 0.0074704255
C45: Number of Diluted Units | D45: =ROUND(+((D38/D16)/(1-D21)),0)-1 -> 2777777 | E45: =D45*100 -> 277777700 | AB45: Interest Payments | AE45: =(L69/D45)*-1 -> 17.769845 | AF45: =AE45/AE40 -> 0.38815283
C47: Debt Proceeds | E47: Gross borrowing | AA47: Distributable Income
...
