Workbook

Sheet Test Site_Proforma
B2: Development pro forma option 1: Test site with no underground parking
B3: WCP TitleCo 3 Inc. — Professional Centre
B4: Jennifer M. Woodfine
B5: January 6, 2026
B6: V1
K7: OPTION 1: TEST SITE NO UNDERGROUND PARKING
B9: 1 | C9: REVENUE
B10: 2
B11: 3 | C11: Rental area summary | F11: Units | G11: Sq. ft. | H11: Rate per sq. ft. | I11: Unit amount | J11: Rent at lease start | K11: Rent at sale
B12: 4 | D12: Underground | F12: 0 | H12: 0 | I12: =G12*H12 -> 0 | J12: =I12 -> 0 | K12: =J12 -> 0
B13: 5 | D13: Retail | F13: 1 | G13: 10600 | H13: 45 | I13: =G13*H13 -> 477000 | J13: =I13 -> 477000 | K13: =J13 -> 477000
B14: 6 | D14: Office — Floor 1 | F14: 1 | G14: 15700 | H14: 38 | I14: =G14*H14 -> 596600 | J14: =I14 -> 596600 | K14: =J14 -> 596600
B15: 7 | D15: Office — Floor 2 | F15: 1 | G15: 18700 | H15: 38 | I15: =G15*H15 -> 710600 | J15: =I15 -> 710600 | K15: =J15 -> 710600
B16: 8 | D16: Office — Floor 3 | F16: 1 | G16: 18700 | H16: 38 | I16: =G16*H16 -> 710600 | J16: =I16 -> 710600 | K16: =J16 -> 710600
B17: 9 | D17: Office — Floor 4 | F17: 0 | G17: 0 | H17: 0 | I17: =G17*H17 -> 0 | J17: =I17 -> 0 | K17: =J17 -> 0
B18: 10 | D18: Office — Floor 5 | F18: 0 | G18: 0 | H18: 0 | I18: =G18*H18 -> 0 | J18: =I18 -> 0 | K18: =J18 -> 0
B19: 11 | D19: Office — Floor 6 | F19: 0 | G19: 0 | H19: 0 | I19: =G19*H19 -> 0 | J19: =I19 -> 0 | K19: =J19 -> 0
B20: 12 | D20: Totals | F20: =SUM(F12:F19) -> 4 | G20: =SUM(G12:G19) -> 63700 | J20: =SUM(J12:J19) -> 2494800 | K20: =SUM(K12:K19) -> 2494800
B21: 13
B22: 14 | C22: Investment valuations
B23: 15 | D23: Office
B24: 16 | E24: 5.500% non-recovery cost | F24: =SUM(J14:J19)*5.5% -> 110979 | G24: =J20-F24 -> 2383821
B25: 17 | E25: Capitalized rent | H25: 0.0625 | I25: =G24/H25 -> 38141136
B26: 18 | D26: Retail
B27: 19 | E27: 5.500% non-recovery cost | F27: =SUM(J12:J13)*5.5% -> 26235 | G27: =J13-F27 -> 450765
B28: 20 | E28: Capitalized rent | H28: 0.0625 | I28: =G27/H28 -> 7212240
B29: 21 | D29: Totals | I29: =SUM(I25:I28) -> 45353376
B30: 22
B31: 23 | C31: Income from tenants
B32: 24 | D32: Office | I32: 0
B33: 25 | D33: Retail | I33: 0
B34: 26 | D34: Total | I34: =I32+I33 -> 0
B35: 27
B36: 28 | C36: TOTAL PROJECTED REVENUE | I36: =I29+I34 -> 45353376
B37: 29
B38: 30 | C38: DEVELOPMENT COSTS
B39: 31
B40: 32 | C40: ACQUISITION COSTS
B41: 33 | D41: Land costs | F41: 3.47 | G41: 800000 | H41: =F41*G41 -> 2776000
B42: 34 | I42: =H41 -> 2776000
...

Sheet Test Site_Report
B2: Development pro forma option 1: Test site with no underground parking
B3: WCP TitleCo 3 Inc. — Professional Centre
B4: Jennifer M. Woodfine
B5: January 6, 2026
B6: V1
O7: OPTION 1: TEST SITE NO UNDERGROUND PARKING
B9: 1 | C9: Procurement stage | D9: $ per sq. ft. | E9: % of total
B10: 2 | C10: Land | D10: ='Test Site_Proforma'!I42/'Test Site_Proforma'!F53 -> 34.665335 | E10: =D10/$D$23 -> 0.11144613
B11: 3 | C11: Total off-site* | D11: ='Test Site_Proforma'!G58 -> 1 | E11: =D11/$D$23 -> 0.0032149157
B12: 4
B13: 5 | C13: Development stage
B14: 6 | C14: Total construction | D14: ='Test Site_Proforma'!I53/'Test Site_Proforma'!F53 -> 213.32 | E14: =D14/$D$23 -> 0.68580581
B15: 7 | C15: Contingency — construction | D15: ='Test Site_Proforma'!I56/'Test Site_Proforma'!F53 -> 10.666 | E15: =D15/$D$23 -> 0.03429029
B16: 8 | C16: Total on-site† | D16: ='Test Site_Proforma'!G59 -> 1 | E16: =D16/$D$23 -> 0.0032149157
B17: 9 | C17: Total Indirect Costs | D17: ='Test Site_Proforma'!I81/'Test Site_Proforma'!F53 -> 24.821684 | E17: =D17/$D$23 -> 0.079799619
B18: 10
B19: 11 | C19: Management stage
B20: 12 | C20: Total inducements | D20: ='Test Site_Proforma'!I71/'Test Site_Proforma'!F53 -> 16.836913 | E20: =D20/$D$23 -> 0.054129256
B21: 13 | C21: Total leasing expense | D21: =('Test Site_Proforma'!H84+'Test Site_Proforma'!H85+'Test Site_Proforma'!H86)/'Test Site_Proforma'!F53 -> 7.5893271 | E21: =D21/$D$23 -> 0.024399046
B22: 14 | C22: Vacant space | D22: ='Test Site_Proforma'!H87/'Test Site_Proforma'!F53 -> 1.1508916 | E22: =D22/$D$23 -> 0.0037000195
B23: 15 | C23: Total project costs | D23: =SUM(D10:D22) -> 311.05015 | E23: =D23/$D$23 -> 1
B24: 16
B25: 17
B26: 18
B27: 19
B28: 20 | C28: *Consists of upgrading city and municipal services, such as installing traffic lights, storm basin, etc.
B29: 21
B30: 22
B31: 23 | C31: †Consists of on-site non-construction development costs, such as levelling land; installing curbs, sidewalks, and hydrants; connecting water; etc.
B32: 24
B33: 25

Sheet Test Site_CAM
B2: Common area maintenance (CAM) budgeting
B3: WCP TitleCo 3 Inc. — Professional Centre
B4: Jennifer M. Woodfine
B5: January 6, 2026
B6: V2
B9: 1 | C9: REVENUE
B10: 2
B11: 3 | C11: Rental area summary | E11: Units | F11: Sq. ft. | G11: Rate per sq. ft. | H11: Unit amount | I11: Rent at lease start | J11: Rent at sale
B12: 4 | D12: Underground | E12: 0 | F12: 0 | G12: 0 | H12: =F12*G12 -> 0 | I12: =H12 -> 0 | J12: =I12 -> 0
B13: 5 | D13: Retail | E13: 1 | F13: 10600 | G13: 45 | H13: =F13*G13 -> 477000 | I13: =H13 -> 477000 | J13: =I13 -> 477000
B14: 6 | D14: Office — Floor 1 | E14: 1 | F14: 15700 | G14: 38 | H14: =F14*G14 -> 596600 | I14: =H14 -> 596600 | J14: =I14 -> 596600
B15: 7 | D15: Office — Floor 2 | E15: 1 | F15: 18700 | G15: 38 | H15: =F15*G15 -> 710600 | I15: =H15 -> 710600 | J15: =I15 -> 710600
B16: 8 | D16: Office — Floor 3 | E16: 1 | F16: 18700 | G16: 38 | H16: =F16*G16 -> 710600 | I16: =H16 -> 710600 | J16: =I16 -> 710600
B17: 9 | D17: Office — Floor 4 | E17: 0 | F17: 0 | G17: 0 | H17: =F17*G17 -> 0 | I17: =H17 -> 0 | J17: =I17 -> 0
B18: 10 | D18: Office — Floor 5 | E18: 0 | F18: 0 | G18: 0 | H18: =F18*G18 -> 0 | I18: =H18 -> 0 | J18: =I18 -> 0
B19: 11 | D19: Office — Floor 6 | E19: 0 | F19: 0 | G19: 0 | H19: =F19*G19 -> 0 | I19: =H19 -> 0 | J19: =I19 -> 0
B20: 12 | D20: Totals | E20: =SUM(E12:E19) -> 4 | F20: =SUM(F12:F19) -> 63700 | I20: =SUM(I12:I19) -> 2494800 | J20: =SUM(J12:J19) -> 2494800
B21: 13
B22: 14
B23: 15 | C23: Retail pylon sign revenue — 4 panels at $250 a month | J23: =4*250*12 -> 12000
B24: 16
B25: 17 | C25: Gross rental income | J25: =J20+J23 -> 2506800
B26: 18
B27: 19 | C27: Recoveries
B28: 20 | C28: Office
B29: 21 | D29: 5.500% non-recovery cost | G29: =+SUM(I14:I19) -> 2017800 | H29: 0.055 | I29: =G29*H29 -> 110979
B30: 22 | C30: Retail
B31: 23 | D31: 5.500% non-recovery cost | G31: =I13 -> 477000 | H31: 0.055 | I31: =G31*H31 -> 26235
B32: 24 | D32: Totals | I32: =SUM(I29:I31) -> 137214 | J32: =I32 -> 137214
B33: 25
B34: 26
B35: 27 | C35: TOTAL PROJECTED REVENUE | J35: =J25-J32 -> 2369586
B36: 28
B37: 29 | C37: EXPENSES | G37: ft2 | H37: Rate ft2 | I37: Cost
B38: 30 | C38: In-house property manager | G38: =$F$20 -> 63700 | I38: 75000
B39: 31 | C39: Common area maintenance | G39: =$F$20 -> 63700 | H39: 5.5 | I39: =G39*H39 -> 350350
B40: 32 | C40: HVAC | G40: =$F$20 -> 63700 | H40: 1.5 | I40: =G40*H40 -> 95550
B41: 33 | C41: Insurance | G41: =$F$20 -> 63700 | H41: 0.75 | I41: =G41*H41 -> 47775
B42: 34 | C42: Local accountant | G42: =$F$20 -> 63700 | I42: 15000
B43: 35 | C43: Local lawyer | G43: =$F$20 -> 63700 | I43: 15000
...

Sheet Test Site_Underground_Proforma
B2: Development pro forma option 2: Test site with underground parking
B3: WCP TitleCo 3 Inc. — Suburban Office
B4: Jennifer M. Woodfine
B5: January 6, 2026
B6: V1
K7: OPTION 2: TEST SITE WITH UNDERGROUND PARKING
B9: 1 | C9: REVENUE
B10: 2
B11: 3 | C11: Rental area summary | F11: Units | G11: Sq. ft. | H11: Rate per sq. ft. | I11: Unit amount | J11: Rent at lease start | K11: Rent at sale
B12: 4 | D12: Underground | F12: 1 | G12: =91*150 -> 13650 | H12: 6 | I12: =G12*H12 -> 81900 | J12: =I12 -> 81900 | K12: =J12 -> 81900
B13: 5 | D13: Retail | F13: 1 | G13: 10600 | H13: 45 | I13: =G13*H13 -> 477000 | J13: =I13 -> 477000 | K13: =J13 -> 477000
B14: 6 | D14: Office — Floor 1 | F14: 1 | G14: 15700 | H14: 38 | I14: =G14*H14 -> 596600 | J14: =I14 -> 596600 | K14: =J14 -> 596600
B15: 7 | D15: Office — Floor 2 | F15: 1 | G15: 18700 | H15: 38 | I15: =G15*H15 -> 710600 | J15: =I15 -> 710600 | K15: =J15 -> 710600
B16: 8 | D16: Office — Floor 3 | F16: 1 | G16: 18700 | H16: 38 | I16: =G16*H16 -> 710600 | J16: =I16 -> 710600 | K16: =J16 -> 710600
B17: 9 | D17: Office — Floor 4 | F17: 1 | G17: 18700 | H17: 38 | I17: =G17*H17 -> 710600 | J17: =I17 -> 710600 | K17: =J17 -> 710600
B18: 10 | D18: Office — Floor 5 | F18: 1 | G18: 18700 | H18: 38 | I18: =G18*H18 -> 710600 | J18: =I18 -> 710600 | K18: =J18 -> 710600
B19: 11 | D19: Office — Floor 6 | F19: 0 | G19: 0 | H19: 0 | I19: =G19*H19 -> 0 | J19: =I19 -> 0 | K19: =J19 -> 0
B20: 12 | D20: Totals | F20: =SUM(F12:F19) -> 7 | G20: =SUM(G12:G19) -> 114750 | J20: =SUM(J12:J19) -> 3997900 | K20: =SUM(K12:K19) -> 3997900
B21: 13
B22: 14 | C22: Investment valuations
B23: 15 | D23: Office
B24: 16 | E24: 5.500% non-recovery cost | F24: =SUM(J14:J19)*5.5% -> 189145 | G24: =J20-F24 -> 3808755
B25: 17 | E25: Capitalized rent | H25: 0.0625 | I25: =G24/H25 -> 60940080
B26: 18 | D26: Retail
B27: 19 | E27: 5.500% non-recovery cost | F27: =SUM(J12:J13)*5.5% -> 30739.5 | G27: =J13-F27 -> 446260.5
B28: 20 | E28: Capitalized rent | H28: 0.0625 | I28: =G27/H28 -> 7140168
B29: 21 | D29: Totals | I29: =SUM(I25:I28) -> 68080248
B30: 22
B31: 23 | C31: Income from tenants
B32: 24 | D32: Office | I32: 0
B33: 25 | D33: Retail | I33: 0
B34: 26 | D34: Total | I34: =I32+I33 -> 0
B35: 27
B36: 28 | C36: TOTAL PROJECTED REVENUE | I36: =I29+I34 -> 68080248
B37: 29
B38: 30 | C38: DEVELOPMENT COSTS
B39: 31
B40: 32 | C40: ACQUISITION COSTS
B41: 33 | D41: Land costs | F41: 3.47 | G41: 800000 | H41: =F41*G41 -> 2776000
B42: 34 | I42: =H41 -> 2776000
...

Sheet Test Site_Underground_Report
B2: Development pro forma option 2: Test site with underground parking
B3: WCP TitleCo 3 Inc. — Suburban Office
B4: Jennifer M. Woodfine
B5: January 6, 2026
B6: V1
O7: OPTION 2: TEST SITE WITH UNDERGROUND PARKING
B9: 1 | C9: Procurement stage | D9: $ per sq. ft. | E9: % of total
B10: 2 | C10: Land | D10: ='Test Site_Underground_Proforma'!I42/'Test Site_Underground_Proforma'!F53 -> 19.758007 | E10: =D10/$D$23 -> 0.072116939
B11: 3 | C11: Total off-site* | D11: ='Test Site_Underground_Proforma'!G58 -> 1 | E11: =D11/$D$23 -> 0.0036500108
B12: 4
B13: 5 | C13: Development stage
B14: 6 | C14: Total construction | D14: ='Test Site_Underground_Proforma'!I53/'Test Site_Underground_Proforma'!F53 -> 197.17291 | E14: =D14/$D$23 -> 0.71968325
B15: 7 | C15: Contingency — Construction | D15: ='Test Site_Underground_Proforma'!I56/'Test Site_Underground_Proforma'!F53 -> 9.8586454 | E15: =D15/$D$23 -> 0.035984162
B16: 8 | C16: Total on-site† | D16: ='Test Site_Underground_Proforma'!G59 -> 1 | E16: =D16/$D$23 -> 0.0036500108
B17: 9 | C17: Total indirect costs | D17: ='Test Site_Underground_Proforma'!I81/'Test Site_Underground_Proforma'!F53 -> 22.212727 | E17: =D17/$D$23 -> 0.081076692
B18: 10
B19: 11 | C19: Management stage
B20: 12 | C20: Total inducements | D20: ='Test Site_Underground_Proforma'!I71/'Test Site_Underground_Proforma'!F53 -> 14.920285 | E20: =D20/$D$23 -> 0.0544592
B21: 13 | C21: Total leasing expense | D21: =('Test Site_Underground_Proforma'!H84+'Test Site_Underground_Proforma'!H85+'Test Site_Underground_Proforma'!H86)/'Test Site_Underground_Proforma'!F53 -> 6.9274439 | E21: =D21/$D$23 -> 0.025285245
B22: 14 | C22: Vacant space | D22: ='Test Site_Underground_Proforma'!H87/'Test Site_Underground_Proforma'!F53 -> 1.1217758 | E22: =D22/$D$23 -> 0.0040944938
B23: 15 | C23: Total project costs | D23: =SUM(D10:D22) -> 273.97179 | E23: =D23/$D$23 -> 1
B24: 16
B25: 17
B26: 18
B27: 19
B28: 20 | C28: *Consists of upgrading city and municipal services, such as installing traffic lights, storm basin, etc.
B29: 21
B30: 22 | C30: †Consists of on-site non-construction development costs, such as levelling land; installing curbs, sidewalks, and hydrants; connecting water; etc.
B31: 23
B32: 24

Sheet Test Site_Underground_CAM
B2: Common area maintenance (CAM) budgeting
B3: WCP TitleCo 3 Inc. — Suburban Office
B4: Jennifer M. Woodfine
B5: January 6, 2026
B6: V2
B9: 1 | C9: REVENUE
B10: 2
B11: 3 | C11: Rental area summary | E11: Units | F11: Sq. ft. | G11: Rate per sq. ft. | H11: Unit amount | I11: Rent at lease start | J11: Rent at sale
B12: 4 | D12: Underground | E12: 1 | F12: =91*150 -> 13650 | G12: 6 | H12: =F12*G12 -> 81900 | I12: =H12 -> 81900 | J12: =I12 -> 81900
B13: 5 | D13: Retail | E13: 1 | F13: 10600 | G13: 45 | H13: =F13*G13 -> 477000 | I13: =H13 -> 477000 | J13: =I13 -> 477000
B14: 6 | D14: Office — Floor 1 | E14: 1 | F14: 15700 | G14: 38 | H14: =F14*G14 -> 596600 | I14: =H14 -> 596600 | J14: =I14 -> 596600
B15: 7 | D15: Office — Floor 2 | E15: 1 | F15: 18700 | G15: 38 | H15: =F15*G15 -> 710600 | I15: =H15 -> 710600 | J15: =I15 -> 710600
B16: 8 | D16: Office — Floor 3 | E16: 1 | F16: 18700 | G16: 38 | H16: =F16*G16 -> 710600 | I16: =H16 -> 710600 | J16: =I16 -> 710600
B17: 9 | D17: Office — Floor 4 | E17: 1 | F17: 18700 | G17: 38 | H17: =F17*G17 -> 710600 | I17: =H17 -> 710600 | J17: =I17 -> 710600
B18: 10 | D18: Office — Floor 5 | E18: 1 | F18: 18700 | G18: 38 | H18: =F18*G18 -> 710600 | I18: =H18 -> 710600 | J18: =I18 -> 710600
B19: 11 | D19: Office — Floor 6 | E19: 0 | F19: 0 | G19: 0 | H19: =F19*G19 -> 0 | I19: =H19 -> 0 | J19: =I19 -> 0
B20: 12 | D20: Totals | E20: =SUM(E12:E19) -> 7 | F20: =SUM(F12:F19) -> 114750 | I20: =SUM(I12:I19) -> 3997900 | J20: =SUM(J12:J19) -> 3997900
B21: 13
B22: 14
B23: 15 | C23: Retail pylon sign revenue — 4 panels at $250 a month | J23: =4*250*12 -> 12000
B24: 16
B25: 17 | C25: Gross rental income | J25: =J20+J23 -> 4009900
B26: 18
B27: 19 | C27: Recoveries
B28: 20 | C28: Office
B29: 21 | D29: 5.500% non-recovery cost | G29: =+SUM(I14:I19) -> 3439000 | H29: 0.055 | I29: =G29*H29 -> 189145
B30: 22 | C30: Retail
B31: 23 | D31: 5.500% non-recovery cost | G31: =I13 -> 477000 | H31: 0.055 | I31: =G31*H31 -> 26235
B32: 24 | D32: Totals | I32: =SUM(I29:I31) -> 215380 | J32: =I32 -> 215380
B33: 25
B34: 26
B35: 27 | C35: TOTAL PROJECTED REVENUE | J35: =J25-J32 -> 3794520
B36: 28
B37: 29 | C37: EXPENSES | G37: ft2 | H37: Rate ft2 | I37: Cost
B38: 30 | C38: In-house property manager | G38: =$F$20 -> 114750 | I38: 75000
B39: 31 | C39: Common area maintenance | G39: =$F$20 -> 114750 | H39: 5.5 | I39: =G39*H39 -> 631125
B40: 32 | C40: HVAC | G40: =$F$20 -> 114750 | H40: 1.5 | I40: =G40*H40 -> 172125
B41: 33 | C41: Insurance | G41: =$F$20 -> 114750 | H41: 0.75 | I41: =G41*H41 -> 86062.5
B42: 34 | C42: Local accountant | G42: =$F$20 -> 114750 | I42: 15000
B43: 35 | C43: Local lawyer | G43: =$F$20 -> 114750 | I43: 15000
...
